Error during execution: All connection attempts failed

Full error traceback:
Traceback (most recent call last):
  File "/home/santiago/ai_automation/langgraph_cloud/apps/.venv/lib/python3.10/site-packages/httpx/_transports/default.py", line 72, in map_httpcore_exceptions
    yield
  File "/home/santiago/ai_automation/langgraph_cloud/apps/.venv/lib/python3.10/site-packages/httpx/_transports/default.py", line 377, in handle_async_request
    resp = await self._pool.handle_async_request(req)
  File "/home/santiago/ai_automation/langgraph_cloud/apps/.venv/lib/python3.10/site-packages/httpcore/_async/connection_pool.py", line 216, in handle_async_request
    raise exc from None
  File "/home/santiago/ai_automation/langgraph_cloud/apps/.venv/lib/python3.10/site-packages/httpcore/_async/connection_pool.py", line 196, in handle_async_request
    response = await connection.handle_async_request(
  File "/home/santiago/ai_automation/langgraph_cloud/apps/.venv/lib/python3.10/site-packages/httpcore/_async/connection.py", line 99, in handle_async_request
    raise exc
  File "/home/santiago/ai_automation/langgraph_cloud/apps/.venv/lib/python3.10/site-packages/httpcore/_async/connection.py", line 76, in handle_async_request
    stream = await self._connect(request)
  File "/home/santiago/ai_automation/langgraph_cloud/apps/.venv/lib/python3.10/site-packages/httpcore/_async/connection.py", line 122, in _connect
    stream = await self._network_backend.connect_tcp(**kwargs)
  File "/home/santiago/ai_automation/langgraph_cloud/apps/.venv/lib/python3.10/site-packages/httpcore/_backends/auto.py", line 30, in connect_tcp
    return await self._backend.connect_tcp(
  File "/home/santiago/ai_automation/langgraph_cloud/apps/.venv/lib/python3.10/site-packages/httpcore/_backends/anyio.py", line 115, in connect_tcp
    with map_exceptions(exc_map):
  File "/usr/lib/python3.10/contextlib.py", line 153, in __exit__
    self.gen.throw(typ, value, traceback)
  File "/home/santiago/ai_automation/langgraph_cloud/apps/.venv/lib/python3.10/site-packages/httpcore/_exceptions.py", line 14, in map_exceptions
    raise to_exc(exc) from exc
httpcore.ConnectError: All connection attempts failed

The above exception was the direct cause of the following exception:

Traceback (most recent call last):
  File "/home/santiago/ai_automation/langgraph_cloud/apps/app_minutes.py", line 42, in main
    thread = await client.threads.create()
  File "/home/santiago/ai_automation/langgraph_cloud/apps/.venv/lib/python3.10/site-packages/langgraph_sdk/client.py", line 834, in create
    return await self.http.post("/threads", json=payload)
  File "/home/santiago/ai_automation/langgraph_cloud/apps/.venv/lib/python3.10/site-packages/langgraph_sdk/client.py", line 220, in post
    r = await self.client.post(path, headers=headers, content=content)
  File "/home/santiago/ai_automation/langgraph_cloud/apps/.venv/lib/python3.10/site-packages/httpx/_client.py", line 1905, in post
    return await self.request(
  File "/home/santiago/ai_automation/langgraph_cloud/apps/.venv/lib/python3.10/site-packages/httpx/_client.py", line 1585, in request
    return await self.send(request, auth=auth, follow_redirects=follow_redirects)
  File "/home/santiago/ai_automation/langgraph_cloud/apps/.venv/lib/python3.10/site-packages/httpx/_client.py", line 1674, in send
    response = await self._send_handling_auth(
  File "/home/santiago/ai_automation/langgraph_cloud/apps/.venv/lib/python3.10/site-packages/httpx/_client.py", line 1702, in _send_handling_auth
    response = await self._send_handling_redirects(
  File "/home/santiago/ai_automation/langgraph_cloud/apps/.venv/lib/python3.10/site-packages/httpx/_client.py", line 1739, in _send_handling_redirects
    response = await self._send_single_request(request)
  File "/home/santiago/ai_automation/langgraph_cloud/apps/.venv/lib/python3.10/site-packages/httpx/_client.py", line 1776, in _send_single_request
    response = await transport.handle_async_request(request)
  File "/home/santiago/ai_automation/langgraph_cloud/apps/.venv/lib/python3.10/site-packages/httpx/_transports/default.py", line 376, in handle_async_request
    with map_httpcore_exceptions():
  File "/usr/lib/python3.10/contextlib.py", line 153, in __exit__
    self.gen.throw(typ, value, traceback)
  File "/home/santiago/ai_automation/langgraph_cloud/apps/.venv/lib/python3.10/site-packages/httpx/_transports/default.py", line 89, in map_httpcore_exceptions
    raise mapped_exc(message) from exc
httpx.ConnectError: All connection attempts failed

